Workbook

Sheet Mission 1 - Question 1
B1: 0.6 | C1: =1-B1 -> 0.4
B2: Appareils | C2: Produits | D2: Total
A3: CA | B3: =D3*B1 -> 182640 | C3: =C1*D3 -> 121760 | D3: 304400
A4: Coût d'achat des produits | B4: 133327 | C4: 62097 | D4: =B4+C4 -> 195424
A5: Marge brute | B5: =B3-B4 -> 49313 | C5: =C3-C4 -> 59663 | D5: =B5+C5 -> 108976
A6: Taux de marque | B6: =B5/B3 -> 0.2700011 | C6: =C5/C3 -> 0.49000493 | D6: =D5/D3 -> 0.35800263
A7: Charges de structure | D7: 106723
A8: Résultat | D8: =D5-D7 -> 2253 | E8: =D8/D3 -> 0.0074014455

Sheet Mission 1 - Question 2
B1: 0.6 | C1: =1-B1 -> 0.4
B2: Appareils | C2: Produits | D2: Total
A3: CA | B3: =D3*B1 -> 182640 | C3: =C1*D3 -> 121760 | D3: 304400
A4: Coût d'achat des produits | B4: 133327 | C4: 62097 | D4: =B4+C4 -> 195424
A5: Marge brute | B5: =B3-B4 -> 49313 | C5: =C3-C4 -> 59663 | D5: =B5+C5 -> 108976
A6: Taux de marque | B6: =B5/B3 -> 0.2700011 | C6: =C5/C3 -> 0.49000493 | D6: =D5/D3 -> 0.35800263
A7: Charges de structure | D7: 106723
A8: Résultat | D8: =D5-D7 -> 2253 | E8: =D8/D3 -> 0.0074014455
A10: Hypothèse 1 | B10: 0.6 | C10: =1-B10 -> 0.4
B11: Appareils | C11: Produits | D11: Total
A12: CA | B12: =D12*B10 -> 182640 | C12: =C10*D12 -> 121760 | D12: 304400
A13: Coût d'achat des produits | B13: =B12*(1-B15) -> 133327.2 | C13: =C12*(1-C15) -> 62097.6 | D13: =B13+C13 -> 195424.8
A14: Marge brute | B14: =B12-B13 -> 49312.8 | C14: =C12-C13 -> 59662.4 | D14: =B14+C14 -> 108975.2
A15: Taux de marque | B15: 0.27 | C15: 0.49 | D15: =D14/D12 -> 0.358
A16: Charges de structure | D16: =D7*0.95 -> 101386.85
A17: Résultat | D17: =D14-D16 -> 7588.35 | E17: =D17/D12 -> 0.024928876
A19: Hypothèse 2 | B19: 0.4 | C19: =1-B19 -> 0.6
B20: Appareils | C20: Produits | D20: Total
A21: CA | B21: =D21*B19 -> 121760 | C21: =C19*D21 -> 182640 | D21: 304400
A22: Coût d'achat des produits | B22: =B21*(1-B24) -> 88884.8 | C22: =C21*(1-C24) -> 93146.4 | D22: =B22+C22 -> 182031.2
A23: Marge brute | B23: =B21-B22 -> 32875.2 | C23: =C21-C22 -> 89493.6 | D23: =B23+C23 -> 122368.8
A24: Taux de marque | B24: =B15 -> 0.27 | C24: =C15 -> 0.49 | D24: =D23/D21 -> 0.402
A25: Charges de structure | D25: =D7 -> 106723
A26: Résultat | D26: =D23-D25 -> 15645.8 | E26: =D26/D21 -> 0.051398817
A28: Hypothèse 3 | B28: 0.6 | C28: =1-B28 -> 0.4
B29: Appareils | C29: Produits | D29: Total
A30: CA | B30: =B3/0.8*0.9 -> 205470 | C30: =C3 -> 121760 | D30: =B30+C30 -> 327230 | G30: ca sans remise | I30: =B3/0.8 -> 228300
A31: Coût d'achat des produits | B31: 133327 | C31: 62097 | D31: =B31+C31 -> 195424 | G31: CA à 10% remise | I31: =I30*0.9 -> 205470
A32: Marge brute | B32: =B30-B31 -> 72143 | C32: =C30-C31 -> 59663 | D32: =B32+C32 -> 131806
A33: Taux de marque | B33: =B32/B30 -> 0.35111208 | C33: =C32/C30 -> 0.49000493 | D33: =D32/D30 -> 0.40279314
A34: Charges de structure | D34: 106723
A35: Résultat | D35: =D32-D34 -> 25083 | E35: =D35/D30 -> 0.076652507
A37: Hypothèse 4 | B37: 0.6 | C37: =1-B37 -> 0.4
B38: Appareils | C38: Produits | D38: Total
A39: CA | B39: =B3 -> 182640 | C39: =C3/0.91*0.97 -> 129788.13 | D39: =B39+C39 -> 312428.13 | G39: CA sans démarque | I39: =C3/0.91 -> 133802.2
A40: Coût d'achat des produits | B40: 133327 | C40: 62097 | D40: =B40+C40 -> 195424 | G40: CA démarque 3% | I40: =I39*0.97 -> 129788.13
A41: Marge brute | B41: =B39-B40 -> 49313 | C41: =C39-C40 -> 67691.132 | D41: =B41+C41 -> 117004.13
A42: Taux de marque | B42: =B41/B39 -> 0.2700011 | C42: =C41/C39 -> 0.52155101 | D42: =D41/D39 -> 0.37449935
A43: Charges de structure | D43: 106723
A44: Résultat | D44: =D41-D43 -> 10281.132 | E44: =D44/D39 -> 0.03290719

Sheet Mission 1 - Question 3
B1: ='Mission 1 - Question 2'!B1 -> 0.6 | C1: ='Mission 1 - Question 2'!C1 -> 0.4
B2: ='Mission 1 - Question 2'!B2 -> Appareils | C2: ='Mission 1 - Question 2'!C2 -> Produits | D2: ='Mission 1 - Question 2'!D2 -> Total
A3: ='Mission 1 - Question 2'!A3 -> CA | B3: ='Mission 1 - Question 2'!B3 -> 182640 | C3: ='Mission 1 - Question 2'!C3 -> 121760 | D3: ='Mission 1 - Question 2'!D3 -> 304400
A4: ='Mission 1 - Question 2'!A4 -> Coût d'achat des produits | B4: ='Mission 1 - Question 2'!B4 -> 133327 | C4: ='Mission 1 - Question 2'!C4 -> 62097 | D4: ='Mission 1 - Question 2'!D4 -> 195424
A5: ='Mission 1 - Question 2'!A5 -> Marge brute | B5: ='Mission 1 - Question 2'!B5 -> 49313 | C5: ='Mission 1 - Question 2'!C5 -> 59663 | D5: ='Mission 1 - Question 2'!D5 -> 108976
A6: ='Mission 1 - Question 2'!A6 -> Taux de marque | B6: ='Mission 1 - Question 2'!B6 -> 0.2700011 | C6: ='Mission 1 - Question 2'!C6 -> 0.49000493 | D6: ='Mission 1 - Question 2'!D6 -> 0.35800263
A7: ='Mission 1 - Question 2'!A7 -> Charges de structure | D7: ='Mission 1 - Question 2'!D7 -> 106723
A8: ='Mission 1 - Question 2'!A8 -> Résultat | D8: ='Mission 1 - Question 2'!D8 -> 2253
A9: Seuil de rentabilité | D9: =D7/D6 -> 298106.75
A11: ='Mission 1 - Question 2'!A10 -> Hypothèse 1 | B11: ='Mission 1 - Question 2'!B10 -> 0.6 | C11: ='Mission 1 - Question 2'!C10 -> 0.4
B12: ='Mission 1 - Question 2'!B11 -> Appareils | C12: ='Mission 1 - Question 2'!C11 -> Produits | D12: ='Mission 1 - Question 2'!D11 -> Total
A13: ='Mission 1 - Question 2'!A12 -> CA | B13: ='Mission 1 - Question 2'!B12 -> 182640 | C13: ='Mission 1 - Question 2'!C12 -> 121760 | D13: ='Mission 1 - Question 2'!D12 -> 304400
A14: ='Mission 1 - Question 2'!A13 -> Coût d'achat des produits | B14: ='Mission 1 - Question 2'!B13 -> 133327.2 | C14: ='Mission 1 - Question 2'!C13 -> 62097.6 | D14: ='Mission 1 - Question 2'!D13 -> 195424.8
A15: ='Mission 1 - Question 2'!A14 -> Marge brute | B15: ='Mission 1 - Question 2'!B14 -> 49312.8 | C15: ='Mission 1 - Question 2'!C14 -> 59662.4 | D15: ='Mission 1 - Question 2'!D14 -> 108975.2
A16: ='Mission 1 - Question 2'!A15 -> Taux de marque | B16: ='Mission 1 - Question 2'!B15 -> 0.27 | C16: ='Mission 1 - Question 2'!C15 -> 0.49 | D16: ='Mission 1 - Question 2'!D15 -> 0.358
A17: ='Mission 1 - Question 2'!A16 -> Charges de structure | D17: ='Mission 1 - Question 2'!D16 -> 101386.85
A18: ='Mission 1 - Question 2'!A17 -> Résultat | D18: ='Mission 1 - Question 2'!D17 -> 7588.35
A19: Seuil de rentabilité | D19: =D17/D16 -> 283203.49
A21: ='Mission 1 - Question 2'!A19 -> Hypothèse 2 | B21: ='Mission 1 - Question 2'!B19 -> 0.4 | C21: ='Mission 1 - Question 2'!C19 -> 0.6
B22: ='Mission 1 - Question 2'!B20 -> Appareils | C22: ='Mission 1 - Question 2'!C20 -> Produits | D22: ='Mission 1 - Question 2'!D20 -> Total
A23: ='Mission 1 - Question 2'!A21 -> CA | B23: ='Mission 1 - Question 2'!B21 -> 121760 | C23: ='Mission 1 - Question 2'!C21 -> 182640 | D23: ='Mission 1 - Question 2'!D21 -> 304400
A24: ='Mission 1 - Question 2'!A22 -> Coût d'achat des produits | B24: ='Mission 1 - Question 2'!B22 -> 88884.8 | C24: ='Mission 1 - Question 2'!C22 -> 93146.4 | D24: ='Mission 1 - Question 2'!D22 -> 182031.2
A25: ='Mission 1 - Question 2'!A23 -> Marge brute | B25: ='Mission 1 - Question 2'!B23 -> 32875.2 | C25: ='Mission 1 - Question 2'!C23 -> 89493.6 | D25: ='Mission 1 - Question 2'!D23 -> 122368.8
A26: ='Mission 1 - Question 2'!A24 -> Taux de marque | B26: ='Mission 1 - Question 2'!B24 -> 0.27 | C26: ='Mission 1 - Question 2'!C24 -> 0.49 | D26: ='Mission 1 - Question 2'!D24 -> 0.402
A27: ='Mission 1 - Question 2'!A25 -> Charges de structure | D27: ='Mission 1 - Question 2'!D25 -> 106723
A28: ='Mission 1 - Question 2'!A26 -> Résultat | D28: ='Mission 1 - Question 2'!D26 -> 15645.8
A29: Seuil de rentabilité | D29: =D27/D26 -> 265480.1
A31: ='Mission 1 - Question 2'!A28 -> Hypothèse 3 | B31: ='Mission 1 - Question 2'!B28 -> 0.6 | C31: ='Mission 1 - Question 2'!C28 -> 0.4
B32: ='Mission 1 - Question 2'!B29 -> Appareils | C32: ='Mission 1 - Question 2'!C29 -> Produits | D32: ='Mission 1 - Question 2'!D29 -> Total
A33: ='Mission 1 - Question 2'!A30 -> CA | B33: ='Mission 1 - Question 2'!B30 -> 205470 | C33: ='Mission 1 - Question 2'!C30 -> 121760 | D33: ='Mission 1 - Question 2'!D30 -> 327230
A34: ='Mission 1 - Question 2'!A31 -> Coût d'achat des produits | B34: ='Mission 1 - Question 2'!B31 -> 133327 | C34: ='Mission 1 - Question 2'!C31 -> 62097 | D34: ='Mission 1 - Question 2'!D31 -> 195424
A35: ='Mission 1 - Question 2'!A32 -> Marge brute | B35: ='Mission 1 - Question 2'!B32 -> 72143 | C35: ='Mission 1 - Question 2'!C32 -> 59663 | D35: ='Mission 1 - Question 2'!D32 -> 131806
A36: ='Mission 1 - Question 2'!A33 -> Taux de marque | B36: ='Mission 1 - Question 2'!B33 -> 0.35111208 | C36: ='Mission 1 - Question 2'!C33 -> 0.49000493 | D36: ='Mission 1 - Question 2'!D33 -> 0.40279314
A37: ='Mission 1 - Question 2'!A34 -> Charges de structure | D37: ='Mission 1 - Question 2'!D34 -> 106723
A38: ='Mission 1 - Question 2'!A35 -> Résultat | D38: ='Mission 1 - Question 2'!D35 -> 25083
A39: Seuil de rentabilité | D39: =D37/D36 -> 264957.34
A41: ='Mission 1 - Question 2'!A37 -> Hypothèse 4 | B41: ='Mission 1 - Question 2'!B37 -> 0.6 | C41: ='Mission 1 - Question 2'!C37 -> 0.4
B42: ='Mission 1 - Question 2'!B38 -> Appareils | C42: ='Mission 1 - Question 2'!C38 -> Produits | D42: ='Mission 1 - Question 2'!D38 -> Total
A43: ='Mission 1 - Question 2'!A39 -> CA | B43: ='Mission 1 - Question 2'!B39 -> 182640 | C43: ='Mission 1 - Question 2'!C39 -> 129788.13 | D43: ='Mission 1 - Question 2'!D39 -> 312428.13
A44: ='Mission 1 - Question 2'!A40 -> Coût d'achat des produits | B44: ='Mission 1 - Question 2'!B40 -> 133327 | C44: ='Mission 1 - Question 2'!C40 -> 62097 | D44: ='Mission 1 - Question 2'!D40 -> 195424
...

Sheet Mission 2 - Question 4
A1: Sept | B1: 500
A2: Comunity management | B2: 2500
A3: Newsletter | B3: 100
A4: Liens sponsorisés | B4: 200
B5: =SUM(B1:B4) -> 3300
A7: Demandes d'abonnement | B7: 20
A9: Coût d'acquisition du client | B9: =B5/B7 -> 165

Sheet Mission 2 - Question 5
A1: Années | B1: N | C1: N+1 | D1: N+2 | E1: N+3
A2: Abonnement moyen annuel | B2: =384/1.2 -> 320 | C2: =384/1.2 -> 320 | D2: =384/1.2 -> 320 | E2: =384/1.2 -> 320 | F2: 384 / 1,2
A3: Coûts de gestion | B3: 240 | C3: 240 | D3: 240 | E3: 240
A4: Coûts de fidélisation | C4: 20 | D4: 20 | E4: 20
A5: Coût d’acquisition | B5: ='Mission 2 - Question 4'!B9 -> 165
A6: Marge nette annuelle | B6: =B2-B3-B4-B5 -> -85 | C6: =C2-C3-C4-C5 -> 60 | D6: =D2-D3-D4-D5 -> 60 | E6: =E2-E3-E4-E5 -> 60 | F6: =SUM(B6:E6) -> 95
A7: Nombre de clients
A8: Marge globale annuelle

Sheet Mission 2 - Question 6
A1: Années | B1: N | C1: N+1 | D1: N+2 | E1: N+3 | F1: Total
A2: Abonnement moyen annuel | B2: =384/1.2 -> 320 | C2: =384/1.2 -> 320 | D2: =384/1.2 -> 320 | E2: =384/1.2 -> 320
A3: Coûts de gestion | B3: 240 | C3: 240 | D3: 240 | E3: 240
A4: Coûts de fidélisation | C4: 20 | D4: 20 | E4: 20
A5: Coût d’acquisition | B5: ='Mission 2 - Question 4'!B9 -> 165
A6: Marge nette annuelle | B6: =B2-B3-B4-B5 -> -85 | C6: =C2-C3-C4-C5 -> 60 | D6: =D2-D3-D4-D5 -> 60 | E6: =E2-E3-E4-E5 -> 60
A7: Nombre de clients | C7: 20 x 0,8 = 16 | D7: 16 x 0,9 = 14,4 | E7: 14,4 x 0,9 = 12,96
B8: 20 | C8: =20*0.8 -> 16 | D8: 14 | E8: 13
A9: Marge globale annuelle | B9: =B8*B6 -> -1700 | C9: =C8*C6 -> 960 | D9: =D8*D6 -> 840 | E9: =E8*E6 -> 780 | F9: =SUM(B9:E9) -> 880
A10: Valeur d'un client | F10: =F9/20 -> 44

Sheet Mission 2 - Question 7
A1: Années | B1: N | C1: N+1 | D1: N+2 | E1: N+3 | F1: Total
A2: Abonnement moyen annuel | B2: =384/1.2 -> 320 | C2: =384/1.2 -> 320 | D2: =384/1.2 -> 320 | E2: =384/1.2 -> 320
A3: Coûts de gestion | B3: 240 | C3: 240 | D3: 240 | E3: 240
A4: Coûts de fidélisation | C4: 40 | D4: 40 | E4: 40
A5: Coût d’acquisition | B5: ='Mission 2 - Question 4'!B9 -> 165
A6: Marge nette annuelle | B6: =B2-B3-B4-B5 -> -85 | C6: =C2-C3-C4-C5 -> 40 | D6: =D2-D3-D4-D5 -> 40 | E6: =E2-E3-E4-E5 -> 40
A7: Nombre de clients | C7: 20 x 0,9 = 18 | D7: 18 x 0,95 = 17,1 | E7: 17 x 0,95 = 16,15
B8: 20 | C8: =B8*0.9 -> 18 | D8: 17 | E8: 16
A9: Marge globale annuelle | B9: =B8*B6 -> -1700 | C9: =C8*C6 -> 720 | D9: =D8*D6 -> 680 | E9: =E8*E6 -> 640 | F9: =SUM(B9:E9) -> 340
A10: Valeur d'un client | F10: =F9/20 -> 17
